Workbook
Name DD_Ts_Fin_Yr_End_Mth: [1]Time!$H$9
Name DD_Ts_Last_Hist_Mth: [1]Time!$H$25
Name FEBRUARI: [2]TB!$H:$H
Name HACC: [2]TB!$AE:$AE
Name JANUARI: [2]TB!$F:$F
Name MARET: [2]TB!$J:$J
Name Model_Name: [1]Overview!$B$2
Name Ts_Fcast_Per_ID: [1]Time!$H$29
Name Ts_Hist_Per_ID: [1]Time!$H$28
Name Ts_Mths_In_Half: [1]Lookups!$D$65
Name Ts_Mths_In_Qtr: [1]Lookups!$D$64
Name Ts_Mths_In_Yr: [1]Lookups!$D$66
Name Ts_Start_Date: [1]Time!$H$13
Name Ts_Term: [1]Time!$H$12

Sheet Detail
A1: PT. XXXXXX
A2: Aging Hutang
A3: Per
A8: Company Code | B8: Time of Payment (angka) | C8: Umur/Aging Hutang | X8: =X9-K9 -> -501152400
A9: Kode OpCo/AP/Afiliasi | B9: Sesuai dengan Kontrak | P9: =SUM(P13:P15) -> 0 | R9: =SUBTOTAL(9,R13:R15) -> -501152400 | S9: =SUBTOTAL(9,S13:S15) -> 0 | T9: =SUBTOTAL(9,T13:T15) -> 0 | U9: =SUBTOTAL(9,U13:U15) -> 0 | V9: =SUBTOTAL(9,V13:V15) -> 0 | W9: =SUBTOTAL(9,W13:W15) -> 0 | X9: =SUBTOTAL(9,X13:X15) -> -501152400
A10: CoCd | B10: TOP | C10: Umur/Aging Hutang | D10: Nama Vendor | E10: Doc. Number | F10: Nomor Invoice | G10: Description Text | H10: Document Date | I10: Posting Date | J10: Due Date | K10: Amount | L10: Kategori Vendor | M10: Kategori Transaksi | N10: Jenis Transaksi | O10: Jenis Pembayaran | P10: Posisi Dokumen | Q10: Status Dokumen | R10: Umur Hutang | X10: TOTAL | Y10: Keterangan Masalah | Z10: Keterangan atas Lain - Lain
J11: Bendahara | R11: Belum ditagih | S11: Belum JT | T11: Jatuh Tempo
T12: 1-45 Days | U12: 46-135 Days | V12: 136-365 Days | W12: Over 365 Days
A13: 3000 | B13: 90 | C13: 20 | D13: REKAYASA ENGINEERING.PT | E13: 5100014442 | F13: 498/RE/X/2025 | G13: SCF.JS.Termin1: Assemen Pabrik Ind56. | H13: 45936 | I13: 45972 | J13: 46061 | K13: -501152400 | L13: Third Parties | M13: Third Parties | N13: Non Semen | O13: SCF | P13: Dokumen di Bendahara | Q13: Siap Bayar | R13: =K13 -> -501152400 | X13: =SUM(R13:W13) -> -501152400 | Y13: Clean & Clear

Sheet SIG-Listing AU Terkonsol +
A1: Nomor | B1: Perusahaan SIG
A2: 1 | B2: SI - Semen Indonesia
A3: =A2+1 -> 2 | B3: SP - Semen Padang
B4: SEPATIM - Sepatim Batamtama
B5: BSA - Bima Sepaja Abadi
A6: =A3+1 -> 3 | B6: ST - Semen Tonasa
A7: =A6+1 -> 4 | B7: SG - Semen Gresik
B8: SMOR - Sinergi Mitra Operasi Rembang
A9: =A7+1 -> 5 | B9: SBI - Solusi Bangun Indonesia
B10: SBA - Solusi Bangun Andalas
B11: SBB - Solusi Bangun Beton
B12: SRC - Solusi Readymix Concrete Indonesia
B13: PLP - Pendawa Lestari Perkasa
B14: ACA - Aroma Cipta Anugrah
B15: CAI - Cipta Anugrah Indonesia
B16: LMI - Langkat Mineral Indonesia
A17: 6 | B17: SIA - Semen Indonesia Aceh
A18: =A17+1 -> 7 | B18: SMBR - Semen Baturaja
B19: BMU - Baturaja Multi Usaha
A20: 8 | B20: IKSG - Industri Kemasan Semen Gresik
A21: 9 | B21: UTSG - United Tractor Semen Gresik
A22: 10 | B22: SMI - Sinergi Mitra Investama
A23: 11 | B23: KIG - Kawasan Industri Gresik
A24: 12 | B24: SIL - Semen Indonesia Logistik
B25: SID - Semen Indonesia Distributor
B26: VULS - Varia Usaha Lintas Segara
B27: VUDS - Varia Usaha Dharma Segara
B28: VUBA - Varia Usaha Bahari
B29: VUFA - Varia Usaha Fabrikasi
A30: =A24+1 -> 13 | B30: SIB - Semen Indonesia Beton
B31: VUB - Varia Usaha Beton
A32: =A30+1 -> 14 | B32: SII - Semen Indonesia International
B33: SIIT - Semen Indonesia International Trading
A34: =A32+1 -> 15 | B34: SKI - Semen Kupang Indonesia
A35: =A34+1 -> 16 | B35: SISI - Sinergi Informatika Semen Indonesia
A36: 17 | B36: SIIB - Semen Indonesia Industri Bangunan
A37: 18 | B37: TLCC - Thang Long Cement
B38: BMU - Baturaja Multi Usaha

Sheet Rekap
B1: Rekap AP Third Party
B2: PT. XXXXXXXX
B3: Per
S4: Rp Juta
B5: Total utang | C5: Afiliasi | G5: BUMN | K5: Swasta | O5: Interco | S5: Total utang JT Belum dibayar
C6: Belum ditagih | D6: Belum JT | E6: Telah JT | F6: Total | G6: Belum ditagih | H6: Belum JT | I6: Telah JT | J6: Total | K6: Belum ditagih | L6: Belum JT | M6: Telah JT | N6: Total | O6: Belum ditagih | P6: Belum JT | Q6: Telah JT | R6: Total
B7: =F7+J7+N7+R7 -> 0 | C7: =SUMIFS(Detail!$R$13:$R$1048576,Detail!$L$13:$L$1048576,Rekap!C5)/10^6 -> 0 | D7: =SUMIFS(Detail!$S$13:$S$1048576,Detail!$L$13:$L$1048576,Rekap!C5)/10^6 -> 0 | E7: =(SUMIFS(Detail!$T$13:$T$1048576,Detail!$L$13:$L$1048576,Rekap!C5)+SUMIFS(Detail!$U$13:$U$1048576,Detail!$L$13:$L$1048576,Rekap!C5)+SUMIFS(Detail!$V$13:$V$1048576,Detail!$L$13:$L$1048576,Rekap!C5)+SUMIFS(Detail!$W$13:$W$1048576,Detail!$L$13:$L$1048576,Rekap!C5))/10^6 -> 0 | F7: =SUM(C7:E7) -> 0 | G7: =SUMIFS(Detail!$R$13:$R$1048576,Detail!$L$13:$L$1048576,Rekap!G5)/10^6 -> 0 | H7: =SUMIFS(Detail!$S$13:$S$1048576,Detail!$L$13:$L$1048576,Rekap!G5)/10^6 -> 0 | I7: =(SUMIFS(Detail!$T$13:$T$1048576,Detail!$L$13:$L$1048576,Rekap!G5)+SUMIFS(Detail!$U$13:$U$1048576,Detail!$L$13:$L$1048576,Rekap!G5)+SUMIFS(Detail!$V$13:$V$1048576,Detail!$L$13:$L$1048576,Rekap!G5)+SUMIFS(Detail!$W$13:$W$1048576,Detail!$L$13:$L$1048576,Rekap!G5))/10^6 -> 0 | J7: =SUM(G7:I7) -> 0 | K7: =SUMIFS(Detail!$R$13:$R$1048576,Detail!$L$13:$L$1048576,Rekap!K5)/10^6 -> 0 | L7: =SUMIFS(Detail!$S$13:$S$1048576,Detail!$L$13:$L$1048576,Rekap!K5)/10^6 -> 0 | M7: =(SUMIFS(Detail!$T$13:$T$1048576,Detail!$L$13:$L$1048576,Rekap!K5)+SUMIFS(Detail!$U$13:$U$1048576,Detail!$L$13:$L$1048576,Rekap!K5)+SUMIFS(Detail!$V$13:$V$1048576,Detail!$L$13:$L$1048576,Rekap!K5)+SUMIFS(Detail!$W$13:$W$1048576,Detail!$L$13:$L$1048576,Rekap!K5))/10^6 -> 0 | N7: =SUM(K7:M7) -> 0 | O7: =SUMIFS(Detail!$R$13:$R$1048576,Detail!$L$13:$L$1048576,Rekap!O5)/10^6 -> 0 | P7: =SUMIFS(Detail!$S$13:$S$1048576,Detail!$L$13:$L$1048576,Rekap!O5)/10^6 -> 0 | Q7: =(SUMIFS(Detail!$T$13:$T$1048576,Detail!$L$13:$L$1048576,Rekap!O5)+SUMIFS(Detail!$U$13:$U$1048576,Detail!$L$13:$L$1048576,Rekap!O5)+SUMIFS(Detail!$V$13:$V$1048576,Detail!$L$13:$L$1048576,Rekap!O5)+SUMIFS(Detail!$W$13:$W$1048576,Detail!$L$13:$L$1048576,Rekap!O5))/10^6 -> 0 | R7: =SUM(O7:Q7) -> 0 | S7: =I7+M7+Q7+E7 -> 0
A8: Asli | B8: 3.9219218e+10 | C8: 66305200 | D8: 6.5703569e+08 | E8: 2.2247739e+10 | F8: 2.297108e+10 | G8: 0 | H8: 0 | I8: 0 | J8: 0 | K8: 1.3419807e+10 | L8: 2.2066004e+09 | M8: 6.2173135e+08 | N8: 1.6248138e+10 | O8: 2.286947e+10
B9: Time of Payment
B11: REKAP UTANG JT BELUM DIBAYAR
B13: Kode | C13: Sebab | G13: Utang JT | H13: Remark
B14: 1 | C14: Dokumen tidak lengkap | G14: =SUMIFS(Detail!$X$13:$X$15,Detail!$Y$13:$Y$15,Rekap!C14)/10^6 -> 0
B15: 2 | C15: Kontrak belum selesai | G15: =SUMIFS(Detail!$X$13:$X$15,Detail!$Y$13:$Y$15,Rekap!C15) -> 0
B16: 3 | C16: Dokumen kembali ke unit kerja | G16: =SUMIFS(Detail!$X$13:$X$15,Detail!$Y$13:$Y$15,Rekap!C16) -> 0
B17: 4 | C17: Menunggu Jadwal Pembayaran / Siap Bayar | G17: =2836237263/10^6 -> 2836.2373
B18: 5 | C18: Ppn | G18: =SUMIFS(Detail!$X$13:$X$15,Detail!$Y$13:$Y$15,Rekap!C18)/10^6 -> 0
B19: 6 | C19: Rekonsiliasi Karena nilai tidak sesuai | G19: =SUMIFS(Detail!$X$13:$X$15,Detail!$Y$13:$Y$15,Rekap!C19) -> 0
B20: 7 | C20: Menjaga Cashflow | G20: =SUMIFS(Detail!$X$13:$X$15,Detail!$Y$13:$Y$15,Rekap!C20) -> 0
B21: 8 | C21: Menunggu JT SCF/SKBND (Inv vendor lunas tetapi SAP/system masih outstanding karena JT SCF/SKBDN) | G21: =SUMIFS(Detail!$X$13:$X$15,Detail!$Y$13:$Y$15,Rekap!C21) -> 0
B22: 9 | C22: Lain-lain | G22: =G23-SUM(G14:G21) -> -2836.2373
G23: =S7 -> 0
C25: INVOICE CLEAR & CLEAN -STATUS DOK DI BENDAHARA
B26: 4 | C26: Menunggu Jadwal Pembayaran / Siap Bayar | D26: Aging | E26: Third Parties | G26: ICS
C27: TOP | E27: Reguler | F27: SCF | G27: Reguler | H27: SCF
C28: 0 | D28: Range Top
D29: > TOP
C30: 7 | D30: Range Top
D31: > TOP
C32: 10 | D32: Range Top
D33: > TOP
C34: 14 | D34: Range Top
D35: > TOP
C36: 15 | D36: Range Top
D37: > TOP
C38: 30 | D38: Range Top
D39: > TOP
C40: 35 | D40: Range Top
D41: > TOP
C42: 37 | D42: Range Top
D43: > TOP
...

Sheet Lis Kategori Vendor
A1: Related Party Intercompany/Afiliasi/BUMN | B1: Related Party Intercompany/Afiliasi/BUMN | C1: Default Alias Table
A2: Rel_Interco Cement | B2: Interco | C2: Semen Padang
A3: Rel_Interco Cement | B3: Interco | C3: Semen Tonasa
A4: Rel_Interco Cement | B4: Interco | C4: Thang Long Cement Company
A5: Rel_Interco Cement | B5: Interco | C5: Semen Gresik
A6: Rel_Interco Cement | B6: Interco | C6: Semen Indonesia Aceh
A7: Rel_Interco Non Cement | B7: Interco | C7: Industri Kemasan Semen Gresik
A8: Rel_Interco Non Cement | B8: Interco | C8: Semen Kupang Indonesia
A9: Rel_Interco Non Cement | B9: Interco | C9: Semen Indonesia Logistik
A10: Rel_Interco Non Cement | B10: Interco | C10: Kawasan Industri Gresik
A11: Rel_Interco Non Cement | B11: Interco | C11: United Tractors Semen Gresik
A12: Rel_Interco Non Cement | B12: Interco | C12: Sinergi Mitra Investama
... A1025: Rel_BUMN | B1025: BUMN | C1025: Third Party

Sheet SIG-Listing AU Terkonsol
A1: Nomor | B1: Perusahaan SIG
A2: 1 | B2: SI - Semen Indonesia
A3: =A2+1 -> 2 | B3: SP - Semen Padang
B4: SEPATIM - Sepatim Batamtama
B5: BSA - Bima Sepaja Abadi
A6: =A3+1 -> 3 | B6: ST - Semen Tonasa
A7: =A6+1 -> 4 | B7: SG - Semen Gresik
B8: SMOR - Sinergi Mitra Operasi Rembang
A9: =A7+1 -> 5 | B9: SBI - Solusi Bangun Indonesia
B10: SBA - Solusi Bangun Andalas
B11: SBB - Solusi Bangun Beton
B12: SRC - Solusi Readymix Concrete Indonesia
B13: PLP - Pendawa Lestari Perkasa
B14: ACA - Aroma Cipta Anugrah
B15: CAI - Cipta Anugrah Indonesia
B16: LMI - Langkat Mineral Indonesia
A17: =A9+1 -> 6 | B17: SIIB - Semen Indonesia Industri Bangunan
A18: =A17+1 -> 7 | B18: IKSG - Industri Kemasan Semen Gresik
A19: =A18+1 -> 8 | B19: UTSG - United Tractor Semen Gresik
A20: =A19+1 -> 9 | B20: SMI - Sinergi Mitra Investama
A21: =A20+1 -> 10 | B21: KIG - Kawasan Industri Gresik
A22: =A21+1 -> 11 | B22: SIL - Semen Indonesia Logistik
B23: SID - Semen Indonesia Distributor
B24: VULS - Varia Usaha Lintas Segara
B25: VUDS - Varia Usaha Dharma Segara
B26: VUBA - Varia Usaha Bahari
B27: VUFA - Varia Usaha Fabrikasi
A28: =A22+1 -> 12 | B28: SIB - Semen Indonesia Beton
B29: VUB - Varia Usaha Beton
A30: =A28+1 -> 13 | B30: SII - Semen Indonesia International
B31: SIIT - Semen Indonesia International Trading
A32: =A30+1 -> 14 | B32: SKI - Semen Kupang Indonesia
A33: =A32+1 -> 15 | B33: SISI - Sinergi Informatika Semen Indonesia
A34: =A33+1 -> 16 | B34: SIA - Semen Indonesia Aceh
A35: =A34+1 -> 17 | B35: TLCC - Thang Long Cement
A36: =A35+1 -> 18 | B36: SMBR - Semen Baturaja
B37: BMU - Baturaja Multi Usaha

Sheet Validation
B2: Kategori Vendor | C2: Kategori Transaksi | D2: Jenis Transaksi | E2: Jenis Pembayaran
B3: BUMN | C3: THIRD PARTIES | D3: SEMEN | E3: SCF
B4: THIRD PARTIES | C4: ICS | D4: NON SEMEN | E4: TT
B5: INTERCO
B6: AFILIASI

Sheet Sheet2

Sheet Sheet1
B3: TOP (Blm & Jatuh Tempo)
B4: 1.Apakah ARR di semua tau Anak Usaha tau?
B5: 2. Untuk menentukan Jatuh Tempo dari TOP perlu adanya Collect Date, dan Collect date tersebut apakah Anak Usaha Tau ?
